#VRML_SIM R2023b utf8

EXTERNPROTO "https://raw.githubusercontent.com/cyberbotics/webots/R2023b/projects/objects/backgrounds/protos/TexturedBackground.proto"
EXTERNPROTO "https://raw.githubusercontent.com/cyberbotics/webots/R2023b/projects/objects/backgrounds/protos/TexturedBackgroundLight.proto"
EXTERNPROTO "https://raw.githubusercontent.com/cyberbotics/webots/R2023b/projects/objects/floors/protos/RectangleArena.proto"

WorldInfo {
  info [
    "The MyBot robot, the robot used in the tutorial of Webots"
  ]
  title "MyBot"
}
Viewpoint {
  orientation 0.19788645505356123 -0.5212011038440718 -0.8301748973909391 5.428176956344463
  position -0.5305635811985615 -0.5925497793367156 0.48960636663236673
}
TexturedBackground {
}
TexturedBackgroundLight {
}
RectangleArena {
}
DEF GREEN_BOX Solid {
  translation 0.25 0.05 0.05
  children [
    Shape {
      appearance PBRAppearance {
        baseColor 0 1 0
        roughness 0.2189099510000001
        metalness 0
      }
      geometry DEF BOX0 Box {
        size 0.1 0.23 0.1
      }
    }
  ]
  name "green box"
  boundingObject Shape {
    appearance PBRAppearance {
      roughness 1.1102230246251565e-16
      metalness 0
    }
    geometry USE BOX0
  }
}
DEF BLUE_BOX Solid {
  translation -0.27 -0.2 0.05
  rotation 0 0 1 0.31
  children [
    Shape {
      appearance PBRAppearance {
        baseColor 0 0 1
        roughness 0.519341125
        metalness 0
      }
      geometry DEF BOX1 Box {
        size 0.1 0.1 0.1
      }
    }
  ]
  name "blue box"
  boundingObject Shape {
    appearance PBRAppearance {
      roughness 1.1102230246251565e-16
      metalness 0
    }
    geometry USE BOX1
  }
}
DEF YELLOW_BOX Solid {
  translation -0.15 0.2 0.05
  rotation 0 0 1 0.4
  children [
    Shape {
      appearance PBRAppearance {
        baseColor 1 1 0
        roughness 0.03934117200000009
        metalness 0
      }
      geometry DEF BOX2 Box {
        size 0.3 0.05 0.1
      }
    }
  ]
  name "yellow box"
  boundingObject Shape {
    appearance PBRAppearance {
      roughness 1.1102230246251565e-16
      metalness 0
    }
    geometry USE BOX2
  }
}
DEF PINK_BOX Solid {
  translation 0.1 -0.42 0.05
  children [
    Shape {
      appearance PBRAppearance {
        baseColor 1 0.1 0.3
        roughness 0.16827074099999995
        metalness 0
      }
      geometry DEF BOX3 Box {
        size 0.08 0.15 0.1
      }
    }
  ]
  name "red box"
  boundingObject Shape {
    appearance PBRAppearance {
      roughness 1.1102230246251565e-16
      metalness 0
    }
    geometry USE BOX3
  }
}
Robot {
  translation 0.06821834690770452 0.02471838953047439 0
  rotation 0 0 1 233.65885793567963
  children [
    Pose {
      translation 0 0 0.0415
      rotation 0 0 1 -1.570796
      children [
        Shape {
          appearance PBRAppearance {
            baseColor 0.0820075 0.364731 0.8
            roughness 1
            metalness 0
          }
          geometry DEF BODY Cylinder {
            height 0.08
            radius 0.045
          }
        }
      ]
    }
    HingeJoint {
      jointParameters HingeJointParameters {
        position 906.273900131978
        axis 0 1 0
        anchor 0 0 0.025
      }
      device [
        RotationalMotor {
          name "left wheel motor"
          maxVelocity 11
        }
        PositionSensor {
          name "left wheel sensor"
        }
      ]
      endPoint Solid {
        translation 0 0.04499999999999999 0.025
        rotation -0.49786481381731607 0.4978649688714019 -0.7101134415945998 1.906629812654969
        children [
          DEF WHEEL Pose {
            rotation 0.577656895078166 0.5771968951617173 -0.5771968951617173 -2.093935
            children [
              Shape {
                appearance PBRAppearance {
                  baseColor 1 0 0
                  roughness 1
                  metalness 0
                }
                geometry Cylinder {
                  height 0.01
                  radius 0.025
                }
              }
            ]
          }
        ]
        name "left wheel"
        boundingObject USE WHEEL
      }
    }
    HingeJoint {
      jointParameters HingeJointParameters {
        position 68.23231999999614
        axis 0 1 0
        anchor 0 0 0.025
      }
      device [
        RotationalMotor {
          name "right wheel motor"
          maxVelocity 11
        }
        PositionSensor {
          name "right wheel sensor"
        }
      ]
      endPoint Solid {
        translation 0 -0.045 0.025
        rotation -0.3468792445415758 0.34687920891993557 0.8714066812489708 4.57517500363367
        children [
          USE WHEEL
        ]
        name "right wheel"
        boundingObject USE WHEEL
      }
    }
    DistanceSensor {
      translation 0.042 0.02 0.063
      rotation 3.38385e-07 7.19235e-09 -1 -0.49920530717958655
      children [
        DEF SENSOR Pose {
          rotation 0.577656895078166 0.5771968951617173 -0.5771968951617173 -2.093935
          children [
            Shape {
              appearance PBRAppearance {
                baseColor 0.975691 0.981481 0.0252992
                roughness 1
                metalness 0
              }
              geometry Cylinder {
                height 0.004
                radius 0.008
              }
            }
          ]
        }
      ]
      name "ds0"
      lookupTable [
        0 1024 0
        0.05 1024 0
        0.15 0 0
      ]
      numberOfRays 2
      aperture 1
    }
    DistanceSensor {
      translation 0.042 -0.02 0.063
      rotation -3.14419e-07 -7.19235e-09 1 -0.5007953071795859
      children [
        USE SENSOR
      ]
      name "ds1"
      lookupTable [
        0 1024 0
        0.05 1024 0
        0.15 0 0
      ]
      numberOfRays 2
      aperture 1
    }
    Shape {
      appearance PBRAppearance {
        baseColor 0.8 0.8 0.8
        baseColorMap ImageTexture {
          url [
            "https://raw.githubusercontent.com/cyberbotics/webots/R2023b/projects/samples/mybot/worlds/textures/mybot.png"
          ]
        }
        roughness 0.5
        metalness 0
      }
      geometry IndexedFaceSet {
        coord Coordinate {
          point [
            0.0435 -0.015 0.038
            0.0435 -0.015 0.023
            0.0455 0 0.023
            0.0435 0.015 0.023
            0.0435 0.015 0.038
            0.0455 0 0.038
          ]
        }
        texCoord TextureCoordinate {
          point [
            0 0
            0.5 0
            1 0
            1 1
            0.5 1
            0 1
          ]
        }
        coordIndex [
          0, 1, 2, 5, -1, 5, 2, 3, 4, -1
        ]
        texCoordIndex [
          5, 0, 1, 4, -1, 4, 1, 2, 3, -1
        ]
        creaseAngle 0.9
      }
    }
  ]
  name "MyBot"
  boundingObject Pose {
    translation 0 0 0.0415
    rotation 0 0 1 -1.570796
    children [
      USE BODY
    ]
  }
  controller "<extern>"
}
